GET / HTTP/1.1" 200 OK
INFO:     102.88.115.14:0 - "GET / HTTP/1.1" 200 OK
INFO:     102.88.115.14:0 - "POST /auth/login HTTP/1.1" 500 Internal Server Error
ERROR:    Exception in ASGI application
Traceback (most recent call last):
  File "/opt/render/project/src/.venv/lib/python3.13/site-packages/uvicorn/protocols/http/h11_impl.py", line 403, in run_asgi
    result = await app(  # type: ignore[func-returns-value]
             ^^^^^^^^^^^^^^^^^^^^^^^^^^^^^^^^^^^^^^^^^^^^^^
        self.scope, self.receive, self.send
        ^^^^^^^^^^^^^^^^^^^^^^^^^^^^^^^^^^^
    )
    ^
  File "/opt/render/project/src/.venv/lib/python3.13/site-packages/uvicorn/middleware/proxy_headers.py", line 60, in __call__
    return await self.app(scope, receive, send)
           ^^^^^^^^^^^^^^^^^^^^^^^^^^^^^^^^^^^^
  File "/opt/render/project/src/.venv/lib/python3.13/site-packages/fastapi/applications.py", line 1133, in __call__
    await super().__call__(scope, receive, send)
  File "/opt/render/project/src/.venv/lib/python3.13/site-packages/starlette/applications.py", line 113, in __call__
    await self.middleware_stack(scope, receive, send)
  File "/opt/render/project/src/.venv/lib/python3.13/site-packages/starlette/middleware/errors.py", line 186, in __call__
    raise exc
  File "/opt/render/project/src/.venv/lib/python3.13/site-packages/starlette/middleware/errors.py", line 164, in __call__
    await self.app(scope, receive, _send)
  File "/opt/render/project/src/.venv/lib/python3.13/site-packages/starlette/middleware/cors.py", line 93, in __call__
    await self.simple_response(scope, receive, send, request_headers=headers)
  File "/opt/render/project/src/.venv/lib/python3.13/site-packages/starlette/middleware/cors.py", line 144, in simple_response
    await self.app(scope, receive, send)
  File "/opt/render/project/src/.venv/lib/python3.13/site-packages/starlette/middleware/exceptions.py", line 63, in __call__
    await wrap_app_handling_exceptions(self.app, conn)(scope, receive, send)
  File "/opt/render/project/src/.venv/lib/python3.13/site-packages/starlette/_exception_handler.py", line 53, in wrapped_app
    raise exc
  File "/opt/render/project/src/.venv/lib/python3.13/site-packages/starlette/_exception_handler.py", line 42, in wrapped_app
    await app(scope, receive, sender)
  File "/opt/render/project/src/.venv/lib/python3.13/site-packages/fastapi/middleware/asyncexitstack.py", line 18, in __call__
    await self.app(scope, receive, send)
  File "/opt/render/project/src/.venv/lib/python3.13/site-packages/starlette/routing.py", line 716, in __call__
    await self.middleware_stack(scope, receive, send)
  File "/opt/render/project/src/.venv/lib/python3.13/site-packages/starlette/routing.py", line 736, in app
    await route.handle(scope, receive, send)
  File "/opt/render/project/src/.venv/lib/python3.13/site-packages/starlette/routing.py", line 290, in handle
    await self.app(scope, receive, send)
  File "/opt/render/project/src/.venv/lib/python3.13/site-packages/fastapi/routing.py", line 123, in app
    await wrap_app_handling_exceptions(app, request)(scope, receive, send)
  File "/opt/render/project/src/.venv/lib/python3.13/site-packages/starlette/_exception_handler.py", line 53, in wrapped_app
    raise exc
  File "/opt/render/project/src/.venv/lib/python3.13/site-packages/starlette/_exception_handler.py", line 42, in wrapped_app
    await app(scope, receive, sender)
  File "/opt/render/project/src/.venv/lib/python3.13/site-packages/fastapi/routing.py", line 109, in app
    response = await f(request)
               ^^^^^^^^^^^^^^^^
  File "/opt/render/project/src/.venv/lib/python3.13/site-packages/fastapi/routing.py", line 387, in app
    raw_response = await run_endpoint_function(
                   ^^^^^^^^^^^^^^^^^^^^^^^^^^^^
    ...<3 lines>...
    )
    ^
  File "/opt/render/project/src/.venv/lib/python3.13/site-packages/fastapi/routing.py", line 288, in run_endpoint_function
    return await dependant.call(**values)
           ^^^^^^^^^^^^^^^^^^^^^^^^^^^^^^
  File "/opt/render/project/src/main.py", line 194, in login
    if not pwd_context.verify(user.pin, stored_user.pin_hash):
           ~~~~~~~~~~~~~~~~~~^^^^^^^^^^^^^^^^^^^^^^^^^^^^^^^^
  File "/opt/render/project/src/.venv/lib/python3.13/site-packages/passlib/context.py", line 2347, in verify
    return record.verify(secret, hash, **kwds)
           ~~~~~~~~~~~~~^^^^^^^^^^^^^^^^^^^^^^
  File "/opt/render/project/src/.venv/lib/python3.13/site-packages/passlib/utils/handlers.py", line 792, in verify
    return consteq(self._calc_checksum(secret), chk)
                   ~~~~~~~~~~~~~~~~~~~^^^^^^^^
  File "/opt/render/project/src/.venv/lib/python3.13/site-packages/passlib/handlers/bcrypt.py", line 591, in _calc_checksum
    self._stub_requires_backend()
    ~~~~~~~~~~~~~~~~~~~~~~~~~~~^^
  File "/opt/render/project/src/.venv/lib/python3.13/site-packages/passlib/utils/handlers.py", line 2254, in _stub_requires_backend
    cls.set_backend()
    ~~~~~~~~~~~~~~~^^
  File "/opt/render/project/src/.venv/lib/python3.13/site-packages/passlib/utils/handlers.py", line 2156, in set_backend
    return owner.set_backend(name, dryrun=dryrun)
           ~~~~~~~~~~~~~~~~~^^^^^^^^^^^^^^^^^^^^^
  File "/opt/render/project/src/.venv/lib/python3.13/site-packages/passlib/utils/handlers.py", line 2176, in set_backend
    raise default_error
passlib.exc.MissingBackendError: bcrypt: no backends available -- recommend you install one (e.g. 'pip install bcrypt')
Need